Workbook
Name Charge_travail: 'Planning initial - 5'!$D$13:$D$42
Name Creer_organi: 'Marche à suivre'!$A$7
Name impression: 'Marche à suivre'!$A$70
Name JB: 'Marche à suivre'!$A$50
Name Microplanning: 'Marche à suivre'!$A$62
Name Organigramme: 'Marche à suivre'!$A$7
Name Planning: 'Marche à suivre'!$A$23
Name Ressources: 'Marche à suivre'!$A$20
Name Suivi: 'Marche à suivre'!$A$64
Name Taches_principales: Suivi!$A$32:$A$41
Name TP_1: Suivi!$A$8:$A$21
Name TP_10: Suivi!$S$8:$S$21
Name TP_2: Suivi!$C$8:$C$21
Name TP_3: Suivi!$E$8:$E$21
Name TP_4: Suivi!$G$8:$G$21
Name TP_5: Suivi!$I$8:$I$21
Name TP_6: Suivi!$K$8:$K$21
Name TP_7: Suivi!$M$8:$M$21
Name TP_8: Suivi!$O$8:$O$21
Name TP_9: Suivi!$Q$8:$Q$21
Name Vues: Ressources!$B$8:$B$13

Sheet Marche à suivre
A1: Marche à suivre pour la planification et gestion du temps d'un projet
B2: Attention, interdiction de remplir les cellules avec le fond blanc
A4: 1.Une fois que les objectifs du projet sont bien définis (séance Kick Off), démarrer le journal de bord
B5: Inscrire le nom du projet et le chef de projet dans l'onglet "Organigramme des tâches"
B6: Remplir dans l'onglet "Journal de bord" la séance Kick Off
A7: 2. Créer un organigramme des tâches
B8: Débuter sur une feuille de papier ou sur un tableau (groupe) | L8: Ne supprimez pas de colonne ou de lignes non utilisées, vous pouvez les masquer si besoin
B9: Insertion/Illustration/ SmartArt/hierarchie/organigramme (si pas déjà présent)
B10: Top niveau : Nom du projet
B11: Niveau "secrétaire de direction" à supprimer (ligne └ )
B12: Des différents niveaux peuvent être créés grâce aux tabulations
B13: Niveau 1 : tâches principales
B14: Une tâche principale est généralement soit un domaine soit un livrable
B15: Niveau 2 : lots de tâches par tâche principale
B16: Un lot de tâches est un ensemble de tâches (et/ou de sous-tâches) qui permettront de réaliser une partie du projet/d'un livrable/d'un domaine
B17: Créer au besoin un niveau 0 (tâche récapitulative = partie de projet par exemple Phase 1, Phase 2, …) | L17: Rappel de théorie sur laquelle est basée ce fichier de planification
B18: Créer au besoin un niveau 3 (tâches) si le lot de tâches est conséquent, No 1.1.1, 1.1.2 …
B19: Mais pas besoin de trop détailler le travail à ce niveau !!
A20: 3. Lister les ressources
B21: Ecrire le nom, prénom et une approximation de l'engagement en % par fonction(s) pour chaque membre de l'équipe
B22: Ne pas supprimer pas de ligne !
A23: 4. Créer le planning initial
A24: 4.1 Choix du planning
B25: Planning initial - 5 : 5 jours/semaine ou 5 p ou 5 h par jour
B26: Planning initial - 10 : 10 demi-jours/semaine ou 10 p ou 10 h par jour
B27: Vous pouvez supprimer ou masquer le planning non utilisé
A28: 4.2 Données du projet
B29: Remplir tout d'abord le nom du projet, votre nom et les dates (format x.x.xx) :
C30: Date du planning : le jour de la réalisation du planning
C31: Mise à jour du planning : si quelques petites modifications sont apportées au cours du projet
C32: En cas de grosse modification, copier un nouveau planning (clic droit sur le nom de la feuille) puis renommer cette feuille avec la nouvelle date au lieu d'initial
C33: Date du début du projet : date du lancement du projet, en notant un lundi si le planning est hebdomadaire
B34: Ce planning peut être hebdomadaire (1 case = 1/2 journée ou 1 jour) ou journalier (1 case est égale à 1 période ou à 1 heure) : faites votre choix à l'aide des listes déroulantes
A35: 4.3 Calendrier
B36: Le premier jour est mis à jour automatiquement, et par défaut les jours/semaines suivant.e.s avec une incrémentation de 1. Vous pouvez modifier le carré jaune en dessous de la date pour créer le bon décalage (week-end, vacances, congé....). Pour toute spéficificité, après avoir ôter la protection, modifiez les formules ou inscrire la date correcte dans la ligne 5 (x.x.xx) et les numéros de jour/semaine dans la ligne 7 (inscrivez simplement le no, le mot semaine ou jour est automatique).
B37: Si vous voulez marquer un saut dans le calendrier (week-end, férié, vacances, hors projet,…) vous pouvez insérer une colonne après avoir fait un clic droit sur la lettre de la première colonne du jour/semaine suivant le saut.
B38: Pour insérer des jours/semaines supplémentaires, sélectionnez toutes les colonnes du dernier jour/semaine - copier - sélectionner la colonne vide après le tableau - coller
A39: 4.4.Travaux à faire - Planification
B40: Pour rappel : les travaux à faire sont répartis en tâches principales (domaines ou livrables) qui sont ensuite divisés en lots de tâches. Il n'est pas nécessaire d'être plus précis lors du planning initial. La planification de chaque tâche doit être faite lorsqu'on aborde un lot de tâches dans le micro-planning (feuille JB) 1 jalon est un rendu ou un moment clé du projet, il a une durée de 0 min
B41: Pour numéroter les lots de tâches, tapez un espace avant la numérotation _1.1, _1.2 …
...

Sheet Organigramme des tâches
A1: Organigramme des tâches | J1: Attention de ne pas déplacer manuellement les zones de texte !
A2: Projet : | C2: Site emprunt multimédia
A3: Chef de projet : | C3: Cléo Forclaz

Sheet Ressources
A1: Ressources
A2: Projet : | C2: =IF(ISBLANK('Organigramme des tâches'!C2),"à remplir dans l'onglet Organigramme des tâches",'Organigramme des tâches'!C2) -> Site emprunt multimédia
A3: Chef de projet : | C3: =IF(ISBLANK('Organigramme des tâches'!C3),"à remplir dans l'onglet Organigramme des tâches",'Organigramme des tâches'!C3) -> Cléo Forclaz
D6: Fonctions, charge en % | K6: Durées totales
A7: Nom | B7: Prénom (obligatoire) | C7: Remarques | D7: Chef de projet | E7: Gestion de projet | F7: Webmaster | G7: Designer | H7: Suppervision | I7: Fonction 6 | J7: Fonction 7 | K7: planifiées dans planning initial-5 | L7: effectuées dans journal de bord
B8: Etat | C8: Ne pas supprimer cette ligne
A9: Jaccobi | B9: Alain | C9: Coach | D9: 0.1 | H9: 1 | K9: ='Planning initial - 5'!E43 -> 0 | L9: ='Journal de bord'!F27 -> 0.029861111
A10: Forclaz | B10: Cléo | C10: Élève | D10: 0.9 | E10: 1 | F10: 1 | G10: 1 | K10: ='Planning initial - 5'!F43 -> 1.9270833 | L10: ='Journal de bord'!G27 -> 0.44375
A11: Pézeril | B11: Mathieu | C11: Client | K11: ='Planning initial - 5'!G43 -> 0.33333333 | L11: ='Journal de bord'!H27 -> 0.029861111
K12: ='Planning initial - 5'!H43 -> 0 | L12: ='Journal de bord'!I27 -> 0
K13: ='Planning initial - 5'!I43 -> 0 | L13: ='Journal de bord'!J27 -> 0
J14: Total | K14: =SUM(K9:K13) -> 2.2604167 | L14: =SUM(L9:L13) -> 0.50347222
D15: =D7 -> Chef de projet | E15: =E7 -> Gestion de projet | F15: =F7 -> Webmaster | G15: =G7 -> Designer | H15: =H7 -> Suppervision | I15: =I7 -> Fonction 6 | J15: =J7 -> Fonction 7 | K15: =K7 -> planifiées dans planning initial-5 | L15: =L7 -> effectuées dans journal de bord
D16: max 100 % par personne

Sheet Planning initial - 5
A1: Planning
A2: Projet : | C2: =IF(ISBLANK('Organigramme des tâches'!C2),"à remplir dans l'onglet Organigramme des tâches",'Organigramme des tâches'!C2) -> Site emprunt multimédia
A3: Chef de projet : | C3: =IF(ISBLANK('Organigramme des tâches'!C3),"à remplir dans l'onglet Organigramme des tâches",'Organigramme des tâches'!C3) -> Cléo Forclaz | V3: =IF(V5=45,1/32,IF(V5=60,1/24,1/3)) -> 0.33333333
A4: Date planning : | C4: 46288 | U4: planning : | V4: hebdomadaire
A5: MàJ planning : | U5: 1 carré de Gantt = | V5: 1 | W5: =IF(OR(V5=45,V5=60),"min","jour") -> jour | Y5: =IF(V5=45,"donc 1 période",IF(V5=60,"donc 1 heure","donc 1 journée complète de 8 heures")) -> donc 1 journée complète de 8 heures
A6: Début projet : | C6: 46279 | U6: Vue Gantt : | V6: Etat
N7: Dates : | O7: =C6 -> 46279 | R7: =IF($V$4="hebdomadaire",O7+4,"") -> 46283 | T7: =IF($V$4="hebdomadaire",O7+V8*7,O7+1) -> 46286 | W7: =IF($V$4="hebdomadaire",T7+4,"") -> 46290 | Y7: =IF($V$4="hebdomadaire",T7+AA8*7,T7+1) -> 46293 | AB7: =IF($V$4="hebdomadaire",Y7+4,"") -> 46297 | AD7: =IF($V$4="hebdomadaire",Y7+AF8*7,Y7+1) -> 46300 | AG7: =IF($V$4="hebdomadaire",AD7+4,"") -> 46304 | AI7: =IF($V$4="hebdomadaire",AD7+AK8*7,AD7+1) -> 46307 | AL7: =IF($V$4="hebdomadaire",AI7+4,"") -> 46311 | AN7: =IF($V$4="hebdomadaire",AI7+AP8*7,AI7+1) -> 46314 | AQ7: =IF($V$4="hebdomadaire",AN7+4,"") -> 46318 | AS7: =IF($V$4="hebdomadaire",AN7+AU8*7,AN7+1) -> 46321 | AV7: =IF($V$4="hebdomadaire",AS7+4,"") -> 46325 | AX7: =IF($V$4="hebdomadaire",AS7+AZ8*7,AS7+1) -> 46328 | BA7: =IF($V$4="hebdomadaire",AX7+4,"") -> 46332 | BC7: =IF($V$4="hebdomadaire",AX7+BE8*7,AX7+1) -> 46335 | BF7: =IF($V$4="hebdomadaire",BC7+4,"") -> 46339 | BH7: =IF($V$4="hebdomadaire",BC7+BJ8*7,BC7+1) -> 46342 | BK7: =IF($V$4="hebdomadaire",BH7+4,"") -> 46346 | BM7: =IF($V$4="hebdomadaire",BH7+BO8*7,BH7+1) -> 46349 | BP7: =IF($V$4="hebdomadaire",BM7+4,"") -> 46353 | BR7: =IF($V$4="hebdomadaire",BM7+BT8*7,BM7+1) -> 46356 | BU7: =IF($V$4="hebdomadaire",BR7+4,"") -> 46360 | BW7: =IF($V$4="hebdomadaire",BR7+BY8*7,BR7+1) -> 46363 | BZ7: =IF($V$4="hebdomadaire",BW7+4,"") -> 46367 | CB7: =IF($V$4="hebdomadaire",BW7+CD8*7,BW7+1) -> 46370 | CE7: =IF($V$4="hebdomadaire",CB7+4,"") -> 46374 | CG7: =IF($V$4="hebdomadaire",CB7+CI8*7,CB7+1) -> 46377 | CJ7: =IF($V$4="hebdomadaire",CG7+4,"") -> 46381 | CL7: =IF($V$4="hebdomadaire",CG7+CN8*7,CG7+1) -> 46384 | CO7: =IF($V$4="hebdomadaire",CL7+4,"") -> 46388 | CQ7: =IF($V$4="hebdomadaire",CL7+CS8*7,CL7+1) -> 46391 | CT7: =IF($V$4="hebdomadaire",CQ7+4,"") -> 46395 | CV7: =IF($V$4="hebdomadaire",CQ7+CX8*7,CQ7+1) -> 46398 | CY7: =IF($V$4="hebdomadaire",CV7+4,"") -> 46402 | DA7: =IF($V$4="hebdomadaire",CV7+DC8*7,CV7+1) -> 46405 | DD7: =IF($V$4="hebdomadaire",DA7+4,"") -> 46409 | DF7: =IF($V$4="hebdomadaire",DA7+DH8*7,DA7+1) -> 46412 | DI7: =IF($V$4="hebdomadaire",DF7+4,"") -> 46416
N8: Décalages : | U8: + | V8: 1 | W8: =IF($V$4="hebdomadaire","sem","jour") -> sem | Z8: + | AA8: 1 | AB8: =IF($V$4="hebdomadaire","sem","jour") -> sem | AE8: + | AF8: 1 | AG8: =IF($V$4="hebdomadaire","sem","jour") -> sem | AJ8: + | AK8: 1 | AL8: =IF($V$4="hebdomadaire","sem","jour") -> sem | AO8: + | AP8: 1 | AQ8: =IF($V$4="hebdomadaire","sem","jour") -> sem | AT8: + | AU8: 1 | AV8: =IF($V$4="hebdomadaire","sem","jour") -> sem | AY8: + | AZ8: 1 | BA8: =IF($V$4="hebdomadaire","sem","jour") -> sem | BD8: + | BE8: 1 | BF8: =IF($V$4="hebdomadaire","sem","jour") -> sem | BI8: + | BJ8: 1 | BK8: =IF($V$4="hebdomadaire","sem","jour") -> sem | BN8: + | BO8: 1 | BP8: =IF($V$4="hebdomadaire","sem","jour") -> sem | BS8: + | BT8: 1 | BU8: =IF($V$4="hebdomadaire","sem","jour") -> sem | BX8: + | BY8: 1 | BZ8: =IF($V$4="hebdomadaire","sem","jour") -> sem | CC8: + | CD8: 1 | CE8: =IF($V$4="hebdomadaire","sem","jour") -> sem | CH8: + | CI8: 1 | CJ8: =IF($V$4="hebdomadaire","sem","jour") -> sem | CM8: + | CN8: 1 | CO8: =IF($V$4="hebdomadaire","sem","jour") -> sem | CR8: + | CS8: 1 | CT8: =IF($V$4="hebdomadaire","sem","jour") -> sem | CW8: + | CX8: 1 | CY8: =IF($V$4="hebdomadaire","sem","jour") -> sem | DB8: + | DC8: 1 | DD8: =IF($V$4="hebdomadaire","sem","jour") -> sem | DG8: + | DH8: 1 | DI8: =IF($V$4="hebdomadaire","sem","jour") -> sem
N9: No jour/semaine : | O9: 1 | T9: =O9+1 -> 2 | Y9: =T9+1 -> 3 | AD9: =Y9+1 -> 4 | AI9: =AD9+1 -> 5 | AN9: =AI9+1 -> 6 | AS9: =AN9+1 -> 7 | AX9: =AS9+1 -> 8 | BC9: =AX9+1 -> 9 | BH9: =BC9+1 -> 10 | BM9: =BH9+1 -> 11 | BR9: =BM9+1 -> 12 | BW9: =BR9+1 -> 13 | CB9: =BW9+1 -> 14 | CG9: =CB9+1 -> 15 | CL9: =CG9+1 -> 16 | CQ9: =CL9+1 -> 17 | CV9: =CQ9+1 -> 18 | DA9: =CV9+1 -> 19 | DF9: =DA9+1 -> 20
E10: Ressources : les collaborateurs,leur fonction et leur implication dans la tâche | N10: Remarques : | BM10: vacances | BR10: vacances | CL10: Ascension | CV10: Pentecôte | DF10: CIE
A11: No tâches ou Jalons | B11: Tâches principales | D11: Charge de | E11: =Ressources!B9 -> Alain | F11: =Ressources!B10 -> Cléo | G11: =Ressources!B11 -> Mathieu | H11: =Ressources!B12 -> 0 | I11: =Ressources!B13 -> 0 | J11: Total | K11: Durées | L11: Remarques | M11: Etat | O11: =IF($V5=45,"P1",IF($V5=60,"H1",O7)) -> 46279 | P11: =IF($V5=45,"P2",IF($V5=60,"H2",O7+1)) -> 46280 | Q11: =IF($V5=45,"P3",IF($V5=60,"H3",O7+2)) -> 46281 | R11: =IF($V5=45,"P4",IF($V5=60,"H4",O7+3)) -> 46282 | S11: =IF($V5=45,"P5",IF($V5=60,"H5",O7+4)) -> 46283 | T11: =IF($V5=45,"P1",IF($V5=60,"H1",T7)) -> 46286 | U11: =IF($V5=45,"P2",IF($V5=60,"H2",T7+1)) -> 46287 | V11: =IF($V5=45,"P3",IF($V5=60,"H3",T7+2)) -> 46288 | W11: =IF($V5=45,"P4",IF($V5=60,"H4",T7+3)) -> 46289 | X11: =IF($V5=45,"P5",IF($V5=60,"H5",T7+4)) -> 46290 | Y11: =IF($V5=45,"P1",IF($V5=60,"H1",Y7)) -> 46293 | Z11: =IF($V5=45,"P2",IF($V5=60,"H2",Y7+1)) -> 46294 | AA11: =IF($V5=45,"P3",IF($V5=60,"H3",Y7+2)) -> 46295 | AB11: =IF($V5=45,"P4",IF($V5=60,"H4",Y7+3)) -> 46296 | AC11: =IF($V5=45,"P5",IF($V5=60,"H5",Y7+4)) -> 46297 | AD11: =IF($V5=45,"P1",IF($V5=60,"H1",AD7)) -> 46300 | AE11: =IF($V5=45,"P2",IF($V5=60,"H2",AD7+1)) -> 46301 | AF11: =IF($V5=45,"P3",IF($V5=60,"H3",AD7+2)) -> 46302 | AG11: =IF($V5=45,"P4",IF($V5=60,"H4",AD7+3)) -> 46303 | AH11: =IF($V5=45,"P5",IF($V5=60,"H5",AD7+4)) -> 46304 | AI11: =IF($V5=45,"P1",IF($V5=60,"H1",AI7)) -> 46307 | AJ11: =IF($V5=45,"P2",IF($V5=60,"H2",AI7+1)) -> 46308 | AK11: =IF($V5=45,"P3",IF($V5=60,"H3",AI7+2)) -> 46309 | AL11: =IF($V5=45,"P4",IF($V5=60,"H4",AI7+3)) -> 46310 | AM11: =IF($V5=45,"P5",IF($V5=60,"H5",AI7+4)) -> 46311 | AN11: =IF($V5=45,"P1",IF($V5=60,"H1",AN7)) -> 46314 | AO11: =IF($V5=45,"P2",IF($V5=60,"H2",AN7+1)) -> 46315 | AP11: =IF($V5=45,"P3",IF($V5=60,"H3",AN7+2)) -> 46316 | AQ11: =IF($V5=45,"P4",IF($V5=60,"H4",AN7+3)) -> 46317 | AR11: =IF($V5=45,"P5",IF($V5=60,"H5",AN7+4)) -> 46318 | AS11: =IF($V5=45,"P1",IF($V5=60,"H1",AS7)) -> 46321 | AT11: =IF($V5=45,"P2",IF($V5=60,"H2",AS7+1)) -> 46322 | AU11: =IF($V5=45,"P3",IF($V5=60,"H3",AS7+2)) -> 46323 | AV11: =IF($V5=45,"P4",IF($V5=60,"H4",AS7+3)) -> 46324 | AW11: =IF($V5=45,"P5",IF($V5=60,"H5",AS7+4)) -> 46325 | AX11: =IF($V5=45,"P1",IF($V5=60,"H1",AX7)) -> 46328 | AY11: =IF($V5=45,"P2",IF($V5=60,"H2",AX7+1)) -> 46329 | AZ11: =IF($V5=45,"P3",IF($V5=60,"H3",AX7+2)) -> 46330 | BA11: =IF($V5=45,"P4",IF($V5=60,"H4",AX7+3)) -> 46331 | BB11: =IF($V5=45,"P5",IF($V5=60,"H5",AX7+4)) -> 46332 | BC11: =IF($V5=45,"P1",IF($V5=60,"H1",BC7)) -> 46335 | BD11: =IF($V5=45,"P2",IF($V5=60,"H2",BC7+1)) -> 46336 | BE11: =IF($V5=45,"P3",IF($V5=60,"H3",BC7+2)) -> 46337 | BF11: =IF($V5=45,"P4",IF($V5=60,"H4",BC7+3)) -> 46338 | BG11: =IF($V5=45,"P5",IF($V5=60,"H5",BC7+4)) -> 46339 | BH11: =IF($V5=45,"P1",IF($V5=60,"H1",BH7)) -> 46342 | BI11: =IF($V5=45,"P2",IF($V5=60,"H2",BH7+1)) -> 46343 | BJ11: =IF($V5=45,"P3",IF($V5=60,"H3",BH7+2)) -> 46344 | BK11: =IF($V5=45,"P4",IF($V5=60,"H4",BH7+3)) -> 46345 | BL11: =IF($V5=45,"P5",IF($V5=60,"H5",BH7+4)) -> 46346 | BM11: =IF($V5=45,"P1",IF($V5=60,"H1",BM7)) -> 46349 | BN11: =IF($V5=45,"P2",IF($V5=60,"H2",BM7+1)) -> 46350 | BO11: =IF($V5=45,"P3",IF($V5=60,"H3",BM7+2)) -> 46351 | BP11: =IF($V5=45,"P4",IF($V5=60,"H4",BM7+3)) -> 46352 | BQ11: =IF($V5=45,"P5",IF($V5=60,"H5",BM7+4)) -> 46353 | BR11: =IF($V5=45,"P1",IF($V5=60,"H1",BR7)) -> 46356 | BS11: =IF($V5=45,"P2",IF($V5=60,"H2",BR7+1)) -> 46357 | BT11: =IF($V5=45,"P3",IF($V5=60,"H3",BR7+2)) -> 46358 | BU11: =IF($V5=45,"P4",IF($V5=60,"H4",BR7+3)) -> 46359 | BV11: =IF($V5=45,"P5",IF($V5=60,"H5",BR7+4)) -> 46360 | BW11: =IF($V5=45,"P1",IF($V5=60,"H1",BW7)) -> 46363 | BX11: =IF($V5=45,"P2",IF($V5=60,"H2",BW7+1)) -> 46364 | BY11: =IF($V5=45,"P3",IF($V5=60,"H3",BW7+2)) -> 46365 | BZ11: =IF($V5=45,"P4",IF($V5=60,"H4",BW7+3)) -> 46366 | CA11: =IF($V5=45,"P5",IF($V5=60,"H5",BW7+4)) -> 46367 | CB11: =IF($V5=45,"P1",IF($V5=60,"H1",CB7)) -> 46370 | CC11: =IF($V5=45,"P2",IF($V5=60,"H2",CB7+1)) -> 46371 | CD11: =IF($V5=45,"P3",IF($V5=60,"H3",CB7+2)) -> 46372 | CE11: =IF($V5=45,"P4",IF($V5=60,"H4",CB7+3)) -> 46373 | CF11: =IF($V5=45,"P5",IF($V5=60,"H5",CB7+4)) -> 46374 | CG11: =IF($V5=45,"P1",IF($V5=60,"H1",CG7)) -> 46377 | CH11: =IF($V5=45,"P2",IF($V5=60,"H2",CG7+1)) -> 46378 | CI11: =IF($V5=45,"P3",IF($V5=60,"H3",CG7+2)) -> 46379 | CJ11: =IF($V5=45,"P4",IF($V5=60,"H4",CG7+3)) -> 46380 | CK11: =IF($V5=45,"P5",IF($V5=60,"H5",CG7+4)) -> 46381 | CL11: =IF($V5=45,"P1",IF($V5=60,"H1",CL7)) -> 46384 | CM11: =IF($V5=45,"P2",IF($V5=60,"H2",CL7+1)) -> 46385 | CN11: =IF($V5=45,"P3",IF($V5=60,"H3",CL7+2)) -> 46386 | CO11: =IF($V5=45,"P4",IF($V5=60,"H4",CL7+3)) -> 46387 | CP11: =IF($V5=45,"P5",IF($V5=60,"H5",CL7+4)) -> 46388 | CQ11: =IF($V5=45,"P1",IF($V5=60,"H1",CQ7)) -> 46391 | CR11: =IF($V5=45,"P2",IF($V5=60,"H2",CQ7+1)) -> 46392 | CS11: =IF($V5=45,"P3",IF($V5=60,"H3",CQ7+2)) -> 46393 | CT11: =IF($V5=45,"P4",IF($V5=60,"H4",CQ7+3)) -> 46394 | CU11: =IF($V5=45,"P5",IF($V5=60,"H5",CQ7+4)) -> 46395 | CV11: =IF($V5=45,"P1",IF($V5=60,"H1",CV7)) -> 46398 | CW11: =IF($V5=45,"P2",IF($V5=60,"H2",CV7+1)) -> 46399 | CX11: =IF($V5=45,"P3",IF($V5=60,"H3",CV7+2)) -> 46400 | CY11: =IF($V5=45,"P4",IF($V5=60,"H4",CV7+3)) -> 46401 | CZ11: =IF($V5=45,"P5",IF($V5=60,"H5",CV7+4)) -> 46402 | DA11: =IF($V5=45,"P1",IF($V5=60,"H1",DA7)) -> 46405 | DB11: =IF($V5=45,"P2",IF($V5=60,"H2",DA7+1)) -> 46406 | DC11: =IF($V5=45,"P3",IF($V5=60,"H3",DA7+2)) -> 46407 | DD11: =IF($V5=45,"P4",IF($V5=60,"H4",DA7+3)) -> 46408 | DE11: =IF($V5=45,"P5",IF($V5=60,"H5",DA7+4)) -> 46409 | DF11: =IF($V5=45,"P1",IF($V5=60,"H1",DF7)) -> 46412 | DG11: =IF($V5=45,"P2",IF($V5=60,"H2",DF7+1)) -> 46413 | DH11: =IF($V5=45,"P3",IF($V5=60,"H3",DF7+2)) -> 46414 | DI11: =IF($V5=45,"P4",IF($V5=60,"H4",DF7+3)) -> 46415 | DJ11: =IF($V5=45,"P5",IF($V5=60,"H5",DF7+4)) -> 46416
C12: Lots de tâches/jalons | D12: travail en h | E12: =IFERROR(HLOOKUP(MAX(Ressources!$D9:$J9),Ressources!$D9:$J15,7,FALSE),"") -> Suppervision | F12: =IFERROR(HLOOKUP(MAX(Ressources!$D10:$J10),Ressources!$D10:$J15,6,FALSE),"") -> Gestion de projet | G12: =IFERROR(HLOOKUP(MAX(Ressources!$D11:$J11),Ressources!$D11:$J15,5,FALSE),"") | H12: =IFERROR(HLOOKUP(MAX(Ressources!$D12:$J12),Ressources!$D12:$J15,4,FALSE),"") | I12: =IFERROR(HLOOKUP(MAX(Ressources!$D13:$J13),Ressources!$D13:$J15,3,FALSE),"") | J12: ressources | K12: prévues en h | L12: (dépendances, détails, …) | M12: Jalon/tâche
A13: Ne pas remplir la dernière ligne, ôtez la protection la feuille (pas de mdp),copier-coller une ou plusieurs ligne, puis protégez à nouveau la feuille (sécurité !!) | N13: =IF(COUNTIF(O13:DJ13,"x")=0,"",COUNTIF(O13:DJ13,"x"))
B14: Administration | D14: =SUM(D15:D16) -> 0.25 | J14: =IF(ISBLANK(C14),"",SUM(E14:I14)) | K14: =IF(ISBLANK(C14),"",IF(D14=0,0,MROUND(D14/J14,"0:15"))) | N14: =IF(COUNTIF(O14:DJ14,"x")=0,"",COUNTIF(O14:DJ14,"x"))
C15: Séances & suivi coach | D15: 0.125 | F15: 1 | J15: =IF(ISBLANK(C15),"",SUM(E15:I15)) -> 1 | K15: =IF(ISBLANK(C15),"",IF(D15=0,0,MROUND(D15/J15,"0:15"))) -> 0.125 | M15: EN COURS | N15: =IF(COUNTIF(O15:DJ15,"x")=0,"",COUNTIF(O15:DJ15,"x")) -> 15 | Q15: x | V15: x | AA15: x | AF15: x | AK15: x | AP15: x | AU15: x | AZ15: x | BE15: x | BJ15: x | BO15: x | BT15: x | BY15: x | CD15: x | CI15: x
C16: Documents de gestion (PV, organigramme, cahier des charges, devis, facturation) | D16: 0.125 | F16: 1 | J16: =IF(ISBLANK(C16),"",SUM(E16:I16)) -> 1 | K16: =IF(ISBLANK(C16),"",IF(D16=0,0,MROUND(D16/J16,"0:15"))) -> 0.125 | M16: EN COURS | N16: =IF(COUNTIF(O16:DJ16,"x")=0,"",COUNTIF(O16:DJ16,"x")) -> 15 | Q16: x | V16: x | AA16: x | AF16: x | AK16: x | AP16: x | AU16: x | AZ16: x | BE16: x | BJ16: x | BO16: x | BT16: x | BY16: x | CD16: x | CI16: x
B17: Design /Preview | D17: =SUM(D18:D20) -> 0.29166667 | J17: =IF(ISBLANK(C17),"",SUM(E17:I17)) | K17: =IF(ISBLANK(C17),"",IF(D17=0,0,MROUND(D17/J17,"0:15"))) | N17: =IF(COUNTIF(O17:DJ17,"x")=0,"",COUNTIF(O17:DJ17,"x"))
C18: Moodboard | D18: 0.083333333 | F18: 1 | J18: =IF(ISBLANK(C18),"",SUM(E18:I18)) -> 1 | K18: =IF(ISBLANK(C18),"",IF(D18=0,0,MROUND(D18/J18,"0:15"))) -> 0.083333333 | M18: TERMINE.E | N18: =IF(COUNTIF(O18:DJ18,"x")=0,"",COUNTIF(O18:DJ18,"x")) -> 1 | V18: x
C19: Croquis | D19: 0.083333333 | F19: 1 | J19: =IF(ISBLANK(C19),"",SUM(E19:I19)) -> 1 | K19: =IF(ISBLANK(C19),"",IF(D19=0,0,MROUND(D19/J19,"0:15"))) -> 0.083333333 | M19: TERMINE.E | N19: =IF(COUNTIF(O19:DJ19,"x")=0,"",COUNTIF(O19:DJ19,"x")) -> 2 | V19: x | AA19: x
C20: WireFrame | D20: 0.125 | F20: 1 | J20: =IF(ISBLANK(C20),"",SUM(E20:I20)) -> 1 | K20: =IF(ISBLANK(C20),"",IF(D20=0,0,MROUND(D20/J20,"0:15"))) -> 0.125 | M20: TERMINE.E | N20: =IF(COUNTIF(O20:DJ20,"x")=0,"",COUNTIF(O20:DJ20,"x")) -> 2 | AA20: x | AF20: x
B21: Base de données | D21: =SUM(D22:D24) -> 0.33333333 | J21: =IF(ISBLANK(C21),"",SUM(E21:I21)) | K21: =IF(ISBLANK(C21),"",IF(D21=0,0,MROUND(D21/J21,"0:15"))) | N21: =IF(COUNTIF(O21:DJ21,"x")=0,"",COUNTIF(O21:DJ21,"x"))
C22: Analyse des colonnes de l'Excel existant à respecter | D22: 0.0625 | G22: 1 | J22: =IF(ISBLANK(C22),"",SUM(E22:I22)) -> 1 | K22: =IF(ISBLANK(C22),"",IF(D22=0,0,MROUND(D22/J22,"0:15"))) -> 0.0625 | M22: A FAIRE | N22: =IF(COUNTIF(O22:DJ22,"x")=0,"",COUNTIF(O22:DJ22,"x")) -> 1 | AF22: x
C23: Conception des tables (élèves, matériel, emprunts, emplacements/armoires) | D23: 0.125 | G23: 1 | J23: =IF(ISBLANK(C23),"",SUM(E23:I23)) -> 1 | K23: =IF(ISBLANK(C23),"",IF(D23=0,0,MROUND(D23/J23,"0:15"))) -> 0.125 | M23: A FAIRE | N23: =IF(COUNTIF(O23:DJ23,"x")=0,"",COUNTIF(O23:DJ23,"x")) -> 2 | AF23: x | AU23: x
C24: Migration des données Excel → base de données | D24: 0.14583333 | G24: 1 | J24: =IF(ISBLANK(C24),"",SUM(E24:I24)) -> 1 | K24: =IF(ISBLANK(C24),"",IF(D24=0,0,MROUND(D24/J24,"0:15"))) -> 0.14583333 | M24: A FAIRE | N24: =IF(COUNTIF(O24:DJ24,"x")=0,"",COUNTIF(O24:DJ24,"x")) -> 2 | AU24: x | AZ24: x
B25: Code | D25: =SUM(D26:D34) -> 1.0069444 | J25: =IF(ISBLANK(C25),"",SUM(E25:I25)) | K25: =IF(ISBLANK(C25),"",IF(D25=0,0,MROUND(D25/J25,"0:15"))) | N25: =IF(COUNTIF(O25:DJ25,"x")=0,"",COUNTIF(O25:DJ25,"x"))
C26: Authentification & rôles (Élève/Prof/Admin) + token lié au compte élève | D26: 0.16666667 | F26: 1 | J26: =IF(ISBLANK(C26),"",SUM(E26:I26)) -> 1 | K26: =IF(ISBLANK(C26),"",IF(D26=0,0,MROUND(D26/J26,"0:15"))) -> 0.16666667 | M26: A FAIRE | N26: =IF(COUNTIF(O26:DJ26,"x")=0,"",COUNTIF(O26:DJ26,"x")) -> 1 | AZ26: x
C27: Règles d'emprunt par rôle (limite élève, illimité Prof, durée prolongée Prof) | D27: 0.0625 | F27: 1 | J27: =IF(ISBLANK(C27),"",SUM(E27:I27)) -> 1 | K27: =IF(ISBLANK(C27),"",IF(D27=0,0,MROUND(D27/J27,"0:15"))) -> 0.0625 | M27: A FAIRE | N27: =IF(COUNTIF(O27:DJ27,"x")=0,"",COUNTIF(O27:DJ27,"x")) -> 1 | BE27: x
C28: Calendrier Admin (vue globale + historique des emprunts) | D28: 0.125 | F28: 1 | J28: =IF(ISBLANK(C28),"",SUM(E28:I28)) -> 1 | K28: =IF(ISBLANK(C28),"",IF(D28=0,0,MROUND(D28/J28,"0:15"))) -> 0.125 | M28: A FAIRE | N28: =IF(COUNTIF(O28:DJ28,"x")=0,"",COUNTIF(O28:DJ28,"x")) -> 2 | BE28: x | BJ28: x
C29: Calendrier Prof/Élève (matériel emprunté, durée) | D29: 0.125 | F29: 1 | J29: =IF(ISBLANK(C29),"",SUM(E29:I29)) -> 1 | K29: =IF(ISBLANK(C29),"",IF(D29=0,0,MROUND(D29/J29,"0:15"))) -> 0.125 | M29: A FAIRE | N29: =IF(COUNTIF(O29:DJ29,"x")=0,"",COUNTIF(O29:DJ29,"x")) -> 1 | BJ29: x
C30: Gestion des emplacements/armoires (visible Admin uniquement) | D30: 0.083333333 | F30: 1 | J30: =IF(ISBLANK(C30),"",SUM(E30:I30)) -> 1 | K30: =IF(ISBLANK(C30),"",IF(D30=0,0,MROUND(D30/J30,"0:15"))) -> 0.083333333 | M30: A FAIRE | N30: =IF(COUNTIF(O30:DJ30,"x")=0,"",COUNTIF(O30:DJ30,"x")) -> 2 | BJ30: x | BO30: x
C31: Rappels automatiques (site + email) pour le retour du matériel | D31: 0.125 | F31: 1 | J31: =IF(ISBLANK(C31),"",SUM(E31:I31)) -> 1 | K31: =IF(ISBLANK(C31),"",IF(D31=0,0,MROUND(D31/J31,"0:15"))) -> 0.125 | M31: A FAIRE | N31: =IF(COUNTIF(O31:DJ31,"x")=0,"",COUNTIF(O31:DJ31,"x")) -> 1 | BO31: x
C32: Page archive par année (fiche, date d'emprunt, date de retour) | D32: 0.10416667 | F32: 1 | J32: =IF(ISBLANK(C32),"",SUM(E32:I32)) -> 1 | K32: =IF(ISBLANK(C32),"",IF(D32=0,0,MROUND(D32/J32,"0:15"))) -> 0.10416667 | M32: A FAIRE | N32: =IF(COUNTIF(O32:DJ32,"x")=0,"",COUNTIF(O32:DJ32,"x")) -> 1 | BT32: x
C33: Photos du matériel + optimisation UI | D33: 0.083333333 | F33: 1 | J33: =IF(ISBLANK(C33),"",SUM(E33:I33)) -> 1 | K33: =IF(ISBLANK(C33),"",IF(D33=0,0,MROUND(D33/J33,"0:15"))) -> 0.083333333 | M33: A FAIRE | N33: =IF(COUNTIF(O33:DJ33,"x")=0,"",COUNTIF(O33:DJ33,"x")) -> 2 | BT33: x | BY33: x
C34: Structure Html/CSS & logique JS | D34: 0.13194444 | F34: 1 | J34: =IF(ISBLANK(C34),"",SUM(E34:I34)) -> 1 | K34: =IF(ISBLANK(C34),"",IF(D34=0,0,MROUND(D34/J34,"0:15"))) -> 0.13541667 | M34: A FAIRE | N34: =IF(COUNTIF(O34:DJ34,"x")=0,"",COUNTIF(O34:DJ34,"x")) -> 1 | BY34: x
B35: Rendu au client | D35: =SUM(D36:D38) -> 0.20833333 | J35: =IF(ISBLANK(C35),"",SUM(E35:I35)) | K35: =IF(ISBLANK(C35),"",IF(D35=0,0,MROUND(D35/J35,"0:15"))) | N35: =IF(COUNTIF(O35:DJ35,"x")=0,"",COUNTIF(O35:DJ35,"x"))
C36: Mise en production de la V1 (hébergement du site existant) | D36: 0.083333333 | F36: 1 | J36: =IF(ISBLANK(C36),"",SUM(E36:I36)) -> 1 | K36: =IF(ISBLANK(C36),"",IF(D36=0,0,MROUND(D36/J36,"0:15"))) -> 0.083333333 | M36: A FAIRE | N36: =IF(COUNTIF(O36:DJ36,"x")=0,"",COUNTIF(O36:DJ36,"x")) -> 2 | BY36: x | CD36: x
C37: Rédaction du README | D37: 0.041666667 | F37: 1 | J37: =IF(ISBLANK(C37),"",SUM(E37:I37)) -> 1 | K37: =IF(ISBLANK(C37),"",IF(D37=0,0,MROUND(D37/J37,"0:15"))) -> 0.041666667 | M37: A FAIRE | N37: =IF(COUNTIF(O37:DJ37,"x")=0,"",COUNTIF(O37:DJ37,"x")) -> 1 | CD37: x
C38: Tests | D38: 0.083333333 | F38: 1 | J38: =IF(ISBLANK(C38),"",SUM(E38:I38)) -> 1 | K38: =IF(ISBLANK(C38),"",IF(D38=0,0,MROUND(D38/J38,"0:15"))) -> 0.083333333 | M38: A FAIRE | N38: =IF(COUNTIF(O38:DJ38,"x")=0,"",COUNTIF(O38:DJ38,"x")) -> 2 | CD38: x | CI38: x
B39: Achevement | D39: =SUM(D40:D41) -> 0.16666667 | J39: =IF(ISBLANK(C39),"",SUM(E39:I39)) | K39: =IF(ISBLANK(C39),"",IF(D39=0,0,MROUND(D39/J39,"0:15"))) | N39: =IF(COUNTIF(O39:DJ39,"x")=0,"",COUNTIF(O39:DJ39,"x"))
C40: Planche de présentation | D40: 0.125 | F40: 1 | J40: =IF(ISBLANK(C40),"",SUM(E40:I40)) -> 1 | K40: =IF(ISBLANK(C40),"",IF(D40=0,0,MROUND(D40/J40,"0:15"))) -> 0.125 | M40: A FAIRE | N40: =IF(COUNTIF(O40:DJ40,"x")=0,"",COUNTIF(O40:DJ40,"x")) -> 1 | CI40: x
...

Sheet Journal de bord
A1: Journal de bord | H1: Projet : | K1: =IF(ISBLANK('Organigramme des tâches'!C2),"à remplir dans l'onglet Organigramme des tâches",'Organigramme des tâches'!C2) -> Site emprunt multimédia | P1: Chef de projet : | Q1: =IF(ISBLANK('Organigramme des tâches'!C3),"à remplir dans l'onglet Organigramme des tâches",'Organigramme des tâches'!C3) -> Cléo Forclaz | T1: Micro planning
K2: Charge totale du projet | L2: =SUM(K4:K26) -> 0.50347222 | O2: F = facturable (noter x)
B3: Date | C3: Début | D3: Fin | E3: Durée | F3: =Ressources!B9 -> Alain | G3: =Ressources!B10 -> Cléo | H3: =Ressources!B11 -> Mathieu | I3: =Ressources!B12 -> 0 | J3: =Ressources!B13 -> 0 | K3: Charge | L3: Tâches principales | M3: No | N3: Lots de tâches | O3: F | P3: Travail effectué | Q3: Décision-remarque | R3: Lieu | T3: Tâches et sous-tâches à faire | U3: Qui ? | V3: Durée | W3: Priorité
B4: Ne pas remplir la première ligne, ôtez la protection la feuille (pas de mdp),copier-coller une ou plusieurs ligne, puis protégez à nouveau la feuille (sécurité !!). Si vous insérez des lignes, recopiez les formules des colonnes E , K et M.
B5: 46281 | C5: 0.42291667 | D5: 0.45277778 | E5: =IF(ISBLANK(D5),"",D5-C5) -> 0.029861111 | F5: x | G5: x | H5: x | K5: =IF(AND(ISBLANK(F5),ISBLANK(G5),ISBLANK(H5),ISBLANK(I5),ISBLANK(J5)),"",COUNTIF(F5:J5,"x")*E5) -> 0.089583333 | L5: Administration | M5: =IF(ISBLANK(L5),"",HLOOKUP(L5,Suivi!A$5:T$6,2,FALSE)) -> TP_1 | N5: Séances & suivi coach | P5: Scéance client | Q5: Mathieu Pézeril envoie l'Excel, les photos, le site et la base de données du TPI ainsi que son propre site/BD. Alain Jaccobi donne l'accès au dossier SharePoint. PV rédigé par Cléo Forclaz. A définir la semaine prochaine : la charge horaire totale du projet. | R5: Sainte-Croix | T5: Envoyer l'Excel, les photos et les anciens sites/BD des TPI | U5: Mathieu Pézeril | W5: 1
B6: 46281 | C6: 0.45347222 | D6: 0.52083333 | E6: =IF(ISBLANK(D6),"",D6-C6) -> 0.067361111 | G6: x | K6: =IF(AND(ISBLANK(F6),ISBLANK(G6),ISBLANK(H6),ISBLANK(I6),ISBLANK(J6)),"",COUNTIF(F6:J6,"x")*E6) -> 0.067361111 | L6: Administration | M6: =IF(ISBLANK(L6),"",HLOOKUP(L6,Suivi!A$5:T$6,2,FALSE)) -> TP_1 | N6: Documents de gestion | P6: PV, Planif, devis | T6: Donner l'accès au dossier SharePoint | U6: Alain Jaccobi | W6: 1
B7: 46288 | C7: 0.34722222 | D7: 0.52083333 | E7: =IF(ISBLANK(D7),"",D7-C7) -> 0.17361111 | G7: x | K7: =IF(AND(ISBLANK(F7),ISBLANK(G7),ISBLANK(H7),ISBLANK(I7),ISBLANK(J7)),"",COUNTIF(F7:J7,"x")*E7) -> 0.17361111 | L7: Administration | M7: =IF(ISBLANK(L7),"",HLOOKUP(L7,Suivi!A$5:T$6,2,FALSE)) -> TP_1 | N7: Documents de gestion | P7: Cahier des charges, planif | T7: Définir la charge horaire totale du projet | U7: Cléo Forclaz | W7: 1
B8: 46295 | C8: 0.34722222 | D8: 0.42361111 | E8: =IF(ISBLANK(D8),"",D8-C8) -> 0.076388889 | G8: x | K8: =IF(AND(ISBLANK(F8),ISBLANK(G8),ISBLANK(H8),ISBLANK(I8),ISBLANK(J8)),"",COUNTIF(F8:J8,"x")*E8) -> 0.076388889 | L8: Administration | M8: =IF(ISBLANK(L8),"",HLOOKUP(L8,Suivi!A$5:T$6,2,FALSE)) -> TP_1 | N8: Repo Git Hub | P8: Création du Repo et coup d'œil des fichiers
B9: 46295 | C9: 0.43055556 | D9: 0.4375 | E9: =IF(ISBLANK(D9),"",D9-C9) -> 0.0069444444 | G9: x | K9: =IF(AND(ISBLANK(F9),ISBLANK(G9),ISBLANK(H9),ISBLANK(I9),ISBLANK(J9)),"",COUNTIF(F9:J9,"x")*E9) -> 0.0069444444 | L9: Administration | M9: =IF(ISBLANK(L9),"",HLOOKUP(L9,Suivi!A$5:T$6,2,FALSE)) -> TP_1 | N9: Séances & suivi coach
B10: 46295 | C10: 0.44097222 | D10: 0.45416667 | E10: =IF(ISBLANK(D10),"",D10-C10) -> 0.013194444 | G10: x | K10: =IF(AND(ISBLANK(F10),ISBLANK(G10),ISBLANK(H10),ISBLANK(I10),ISBLANK(J10)),"",COUNTIF(F10:J10,"x")*E10) -> 0.013194444 | L10: Administration | M10: =IF(ISBLANK(L10),"",HLOOKUP(L10,Suivi!A$5:T$6,2,FALSE)) -> TP_1 | N10: Repo Git Hub | P10: PV
B11: mer 30 sept 26 | C11: 0.45833333 | D11: 0.52083333 | E11: 0.076388889 | G11: x | K11: 0.076388889 | L11: Code | M11: =IF(ISBLANK(L11),"",HLOOKUP(L11,Suivi!A$5:T$6,2,FALSE)) -> TP_3 | N11: Affichage | P11: Tentative d'affichage
E12: =IF(ISBLANK(D12),"",D12-C12) | K12: =IF(AND(ISBLANK(F12),ISBLANK(G12),ISBLANK(H12),ISBLANK(I12),ISBLANK(J12)),"",COUNTIF(F12:J12,"x")*E12) | M12: =IF(ISBLANK(L12),"",HLOOKUP(L12,Suivi!A$5:T$6,2,FALSE))
E13: =IF(ISBLANK(D13),"",D13-C13) | K13: =IF(AND(ISBLANK(F13),ISBLANK(G13),ISBLANK(H13),ISBLANK(I13),ISBLANK(J13)),"",COUNTIF(F13:J13,"x")*E13) | M13: =IF(ISBLANK(L13),"",HLOOKUP(L13,Suivi!A$5:T$6,2,FALSE))
E14: =IF(ISBLANK(D14),"",D14-C14) | K14: =IF(AND(ISBLANK(F14),ISBLANK(G14),ISBLANK(H14),ISBLANK(I14),ISBLANK(J14)),"",COUNTIF(F14:J14,"x")*E14) | M14: =IF(ISBLANK(L14),"",HLOOKUP(L14,Suivi!A$5:T$6,2,FALSE))
E15: =IF(ISBLANK(D15),"",D15-C15) | K15: =IF(AND(ISBLANK(F15),ISBLANK(G15),ISBLANK(H15),ISBLANK(I15),ISBLANK(J15)),"",COUNTIF(F15:J15,"x")*E15) | M15: =IF(ISBLANK(L15),"",HLOOKUP(L15,Suivi!A$5:T$6,2,FALSE))
E16: =IF(ISBLANK(D16),"",D16-C16) | K16: =IF(AND(ISBLANK(F16),ISBLANK(G16),ISBLANK(H16),ISBLANK(I16),ISBLANK(J16)),"",COUNTIF(F16:J16,"x")*E16) | M16: =IF(ISBLANK(L16),"",HLOOKUP(L16,Suivi!A$5:T$6,2,FALSE))
E17: =IF(ISBLANK(D17),"",D17-C17) | K17: =IF(AND(ISBLANK(F17),ISBLANK(G17),ISBLANK(H17),ISBLANK(I17),ISBLANK(J17)),"",COUNTIF(F17:J17,"x")*E17) | M17: =IF(ISBLANK(L17),"",HLOOKUP(L17,Suivi!A$5:T$6,2,FALSE))
E18: =IF(ISBLANK(D18),"",D18-C18) | K18: =IF(AND(ISBLANK(F18),ISBLANK(G18),ISBLANK(H18),ISBLANK(I18),ISBLANK(J18)),"",COUNTIF(F18:J18,"x")*E18) | M18: =IF(ISBLANK(L18),"",HLOOKUP(L18,Suivi!A$5:T$6,2,FALSE))
E19: =IF(ISBLANK(D19),"",D19-C19) | K19: =IF(AND(ISBLANK(F19),ISBLANK(G19),ISBLANK(H19),ISBLANK(I19),ISBLANK(J19)),"",COUNTIF(F19:J19,"x")*E19) | M19: =IF(ISBLANK(L19),"",HLOOKUP(L19,Suivi!A$5:T$6,2,FALSE))
E20: =IF(ISBLANK(D20),"",D20-C20) | K20: =IF(AND(ISBLANK(F20),ISBLANK(G20),ISBLANK(H20),ISBLANK(I20),ISBLANK(J20)),"",COUNTIF(F20:J20,"x")*E20) | M20: =IF(ISBLANK(L20),"",HLOOKUP(L20,Suivi!A$5:T$6,2,FALSE))
E21: =IF(ISBLANK(D21),"",D21-C21) | K21: =IF(AND(ISBLANK(F21),ISBLANK(G21),ISBLANK(H21),ISBLANK(I21),ISBLANK(J21)),"",COUNTIF(F21:J21,"x")*E21) | M21: =IF(ISBLANK(L21),"",HLOOKUP(L21,Suivi!A$5:T$6,2,FALSE))
E22: =IF(ISBLANK(D22),"",D22-C22) | K22: =IF(AND(ISBLANK(F22),ISBLANK(G22),ISBLANK(H22),ISBLANK(I22),ISBLANK(J22)),"",COUNTIF(F22:J22,"x")*E22) | M22: =IF(ISBLANK(L22),"",HLOOKUP(L22,Suivi!A$5:T$6,2,FALSE))
E23: =IF(ISBLANK(D23),"",D23-C23) | K23: =IF(AND(ISBLANK(F23),ISBLANK(G23),ISBLANK(H23),ISBLANK(I23),ISBLANK(J23)),"",COUNTIF(F23:J23,"x")*E23) | M23: =IF(ISBLANK(L23),"",HLOOKUP(L23,Suivi!A$5:T$6,2,FALSE))
... E25: =IF(ISBLANK(D25),"",D25-C25) | K25: =IF(AND(ISBLANK(F25),ISBLANK(G25),ISBLANK(H25),ISBLANK(I25),ISBLANK(J25)),"",COUNTIF(F25:J25,"x")*E25) | M25: =IF(ISBLANK(L25),"",HLOOKUP(L25,Suivi!A$5:T$6,2,FALSE))
B26: Ne pas remplir la dernière ligne, ôtez la protection la feuille (pas de mdp),copier-coller une ou plusieurs ligne, puis protégez à nouveau la feuille (sécurité !!). Si vous insérez des lignes, recopiez les formules des colonnes E , K et M.
E27: Totaux | F27: =SUMIF(F4:F26,"x",$E4:$E26) -> 0.029861111 | G27: =SUMIF(G4:G26,"x",$E4:$E26) -> 0.44375 | H27: =SUMIF(H4:H26,"x",$E4:$E26) -> 0.029861111 | I27: =SUMIF(I4:I26,"x",$E4:$E26) -> 0 | J27: =SUMIF(J4:J26,"x",$E4:$E26) -> 0 | K27: =SUM(K4:K26) -> 0.50347222 | L27: Total facturable | N27: =SUMIF(O4:O26,"x",K4:K26) -> 0 | O27: =IF(N27>0,N27/K27,"0 "%) -> 0
L28: Total non-facturable | N28: =K27-N27 -> 0.50347222 | O28: =IF(N28>0,N28/K27,"0 %") -> 1

Sheet Suivi
A1: Suivi de projet | G1: Projet : | H1: =IF(ISBLANK('Organigramme des tâches'!C2),"à remplir dans l'onglet Organigramme des tâches",'Organigramme des tâches'!C2) -> Site emprunt multimédia | O1: Chef de projet : | Q1: =IF(ISBLANK('Organigramme des tâches'!C3),"à remplir dans l'onglet Organigramme des tâches",'Organigramme des tâches'!C3) -> Cléo Forclaz
A3: noter ci-dessous les types de tâches/lots de travaux selon votre organigramme des tâches
A4: Tâches principales | H4: Charge totale du projet | I4: =B22+D22+F22+H22+J22+L22+N22+P22+R22+T22 -> 0.50347222 | J4: h | K4: =IF(I4='Journal de bord'!L2,"OK total Suivi = total JB",IF(I4<'Journal de bord'!L2,"Attention total Suivi < total JB","Attention total Suivi > total JB")) -> OK total Suivi = total JB | N4: =IF(I4='Journal de bord'!L2,"",IF(I4<'Journal de bord'!L2,"il manque "&TEXT('Journal de bord'!L2-I4,"h:mm")&" h","il y a "&TEXT(Suivi!I4-'Journal de bord'!L2,"h:mm")&" h en trop"))
A5: Administration | C5: Design /Preview | E5: Code | G5: Base de données | I5: Rendu au client | K5: Achevement
A6: TP_1 | C6: TP_2 | E6: TP_3 | G6: TP_4 | I6: TP_5 | K6: TP_6 | M6: TP_7 | O6: TP_8 | Q6: TP_9 | S6: TP_10
A7: Lots de tâches | B7: durée | C7: Lots de tâches | D7: durée | E7: Lots de tâches | F7: durée | G7: Lots de tâches | H7: durée | I7: Lots de tâches | J7: durée | K7: Lots de tâches | L7: durée | M7: Lots de tâches | N7: durée | O7: Lots de tâches | P7: durée | Q7: Lots de tâches | R7: durée | S7: Lots de tâches | T7: durée
A8: Séances & suivi coach | B8: =IF(ISBLANK(A8),"",SUMIF('Journal de bord'!N:N,A8,'Journal de bord'!K:K)) -> 0.096527778 | C8: Moodboard | D8: =IF(ISBLANK(C8),"",SUMIF('Journal de bord'!N:N,C8,'Journal de bord'!K:K)) -> 0 | E8: Authentification & rôles (Élève/Prof/Admin) + token lié au compte élève | F8: =IF(ISBLANK(E8),"",SUMIF('Journal de bord'!N:N,E8,'Journal de bord'!K:K)) -> 0 | G8: Analyse des colonnes de l'Excel existant à respecter | H8: =IF(ISBLANK(G8),"",SUMIF('Journal de bord'!N:N,G8,'Journal de bord'!K:K)) -> 0 | I8: Mise en production de la V1 (hébergement du site existant) | J8: =IF(ISBLANK(I8),"",SUMIF('Journal de bord'!N:N,I8,'Journal de bord'!K:K)) -> 0 | K8: Planche de présentation | L8: =IF(ISBLANK(K8),"",SUMIF('Journal de bord'!N:N,K8,'Journal de bord'!K:K)) -> 0 | N8: =IF(ISBLANK(M8),"",SUMIF('Journal de bord'!N:N,M8,'Journal de bord'!K:K)) | P8: =IF(ISBLANK(O8),"",SUMIF('Journal de bord'!N:N,O8,'Journal de bord'!K:K)) | R8: =IF(ISBLANK(Q8),"",SUMIF('Journal de bord'!N:N,Q8,'Journal de bord'!K:K)) | T8: =IF(ISBLANK(S8),"",SUMIF('Journal de bord'!N:N,S8,'Journal de bord'!K:K))
A9: Documents de gestion | B9: =IF(ISBLANK(A9),"",SUMIF('Journal de bord'!N:N,A9,'Journal de bord'!K:K)) -> 0.24097222 | C9: Croquis | D9: =IF(ISBLANK(C9),"",SUMIF('Journal de bord'!N:N,C9,'Journal de bord'!K:K)) -> 0 | E9: Règles d'emprunt par rôle (limite élève, illimité Prof, durée prolongée Prof) | F9: =IF(ISBLANK(E9),"",SUMIF('Journal de bord'!N:N,E9,'Journal de bord'!K:K)) -> 0 | G9: Conception des tables (élèves, matériel, emprunts, emplacements/armoires) | H9: =IF(ISBLANK(G9),"",SUMIF('Journal de bord'!N:N,G9,'Journal de bord'!K:K)) -> 0 | I9: Rédaction du README | J9: =IF(ISBLANK(I9),"",SUMIF('Journal de bord'!N:N,I9,'Journal de bord'!K:K)) -> 0 | K9: Archivage | L9: =IF(ISBLANK(K9),"",SUMIF('Journal de bord'!N:N,K9,'Journal de bord'!K:K)) -> 0 | N9: =IF(ISBLANK(M9),"",SUMIF('Journal de bord'!N:N,M9,'Journal de bord'!K:K)) | P9: =IF(ISBLANK(O9),"",SUMIF('Journal de bord'!N:N,O9,'Journal de bord'!K:K)) | R9: =IF(ISBLANK(Q9),"",SUMIF('Journal de bord'!N:N,Q9,'Journal de bord'!K:K)) | T9: =IF(ISBLANK(S9),"",SUMIF('Journal de bord'!N:N,S9,'Journal de bord'!K:K))
A10: Repo Git Hub | B10: =IF(ISBLANK(A10),"",SUMIF('Journal de bord'!N:N,A10,'Journal de bord'!K:K)) -> 0.089583333 | C10: WireFrame | D10: =IF(ISBLANK(C10),"",SUMIF('Journal de bord'!N:N,C10,'Journal de bord'!K:K)) -> 0 | E10: Calendrier Admin (vue globale + historique des emprunts) | F10: =IF(ISBLANK(E10),"",SUMIF('Journal de bord'!N:N,E10,'Journal de bord'!K:K)) -> 0 | G10: Migration des données Excel → base de données | H10: =IF(ISBLANK(G10),"",SUMIF('Journal de bord'!N:N,G10,'Journal de bord'!K:K)) -> 0 | I10: Tests | J10: =IF(ISBLANK(I10),"",SUMIF('Journal de bord'!N:N,I10,'Journal de bord'!K:K)) -> 0 | L10: =IF(ISBLANK(K10),"",SUMIF('Journal de bord'!N:N,K10,'Journal de bord'!K:K)) | N10: =IF(ISBLANK(M10),"",SUMIF('Journal de bord'!N:N,M10,'Journal de bord'!K:K)) | P10: =IF(ISBLANK(O10),"",SUMIF('Journal de bord'!N:N,O10,'Journal de bord'!K:K)) | R10: =IF(ISBLANK(Q10),"",SUMIF('Journal de bord'!N:N,Q10,'Journal de bord'!K:K)) | T10: =IF(ISBLANK(S10),"",SUMIF('Journal de bord'!N:N,S10,'Journal de bord'!K:K))
B11: =IF(ISBLANK(A11),"",SUMIF('Journal de bord'!N:N,A11,'Journal de bord'!K:K)) | D11: =IF(ISBLANK(C11),"",SUMIF('Journal de bord'!N:N,C11,'Journal de bord'!K:K)) | E11: Calendrier Prof/Élève (matériel emprunté, durée) | F11: =IF(ISBLANK(E11),"",SUMIF('Journal de bord'!N:N,E11,'Journal de bord'!K:K)) -> 0 | H11: =IF(ISBLANK(G11),"",SUMIF('Journal de bord'!N:N,G11,'Journal de bord'!K:K)) | J11: =IF(ISBLANK(I11),"",SUMIF('Journal de bord'!N:N,I11,'Journal de bord'!K:K)) | L11: =IF(ISBLANK(K11),"",SUMIF('Journal de bord'!N:N,K11,'Journal de bord'!K:K)) | N11: =IF(ISBLANK(M11),"",SUMIF('Journal de bord'!N:N,M11,'Journal de bord'!K:K)) | P11: =IF(ISBLANK(O11),"",SUMIF('Journal de bord'!N:N,O11,'Journal de bord'!K:K)) | R11: =IF(ISBLANK(Q11),"",SUMIF('Journal de bord'!N:N,Q11,'Journal de bord'!K:K)) | T11: =IF(ISBLANK(S11),"",SUMIF('Journal de bord'!N:N,S11,'Journal de bord'!K:K))
B12: =IF(ISBLANK(A12),"",SUMIF('Journal de bord'!N:N,A12,'Journal de bord'!K:K)) | D12: =IF(ISBLANK(C12),"",SUMIF('Journal de bord'!N:N,C12,'Journal de bord'!K:K)) | E12: Gestion des emplacements/armoires (visible Admin uniquement) | F12: =IF(ISBLANK(E12),"",SUMIF('Journal de bord'!N:N,E12,'Journal de bord'!K:K)) -> 0 | H12: =IF(ISBLANK(G12),"",SUMIF('Journal de bord'!N:N,G12,'Journal de bord'!K:K)) | J12: =IF(ISBLANK(I12),"",SUMIF('Journal de bord'!N:N,I12,'Journal de bord'!K:K)) | L12: =IF(ISBLANK(K12),"",SUMIF('Journal de bord'!N:N,K12,'Journal de bord'!K:K)) | N12: =IF(ISBLANK(M12),"",SUMIF('Journal de bord'!N:N,M12,'Journal de bord'!K:K)) | P12: =IF(ISBLANK(O12),"",SUMIF('Journal de bord'!N:N,O12,'Journal de bord'!K:K)) | R12: =IF(ISBLANK(Q12),"",SUMIF('Journal de bord'!N:N,Q12,'Journal de bord'!K:K)) | T12: =IF(ISBLANK(S12),"",SUMIF('Journal de bord'!N:N,S12,'Journal de bord'!K:K))
B13: =IF(ISBLANK(A13),"",SUMIF('Journal de bord'!N:N,A13,'Journal de bord'!K:K)) | D13: =IF(ISBLANK(C13),"",SUMIF('Journal de bord'!N:N,C13,'Journal de bord'!K:K)) | E13: Rappels automatiques (site + email) pour le retour du matériel | F13: =IF(ISBLANK(E13),"",SUMIF('Journal de bord'!N:N,E13,'Journal de bord'!K:K)) -> 0 | H13: =IF(ISBLANK(G13),"",SUMIF('Journal de bord'!N:N,G13,'Journal de bord'!K:K)) | J13: =IF(ISBLANK(I13),"",SUMIF('Journal de bord'!N:N,I13,'Journal de bord'!K:K)) | L13: =IF(ISBLANK(K13),"",SUMIF('Journal de bord'!N:N,K13,'Journal de bord'!K:K)) | N13: =IF(ISBLANK(M13),"",SUMIF('Journal de bord'!N:N,M13,'Journal de bord'!K:K)) | P13: =IF(ISBLANK(O13),"",SUMIF('Journal de bord'!N:N,O13,'Journal de bord'!K:K)) | R13: =IF(ISBLANK(Q13),"",SUMIF('Journal de bord'!N:N,Q13,'Journal de bord'!K:K)) | T13: =IF(ISBLANK(S13),"",SUMIF('Journal de bord'!N:N,S13,'Journal de bord'!K:K))
B14: =IF(ISBLANK(A14),"",SUMIF('Journal de bord'!N:N,A14,'Journal de bord'!K:K)) | D14: =IF(ISBLANK(C14),"",SUMIF('Journal de bord'!N:N,C14,'Journal de bord'!K:K)) | E14: Page archive par année (fiche, date d'emprunt, date de retour) | F14: =IF(ISBLANK(E14),"",SUMIF('Journal de bord'!N:N,E14,'Journal de bord'!K:K)) -> 0 | H14: =IF(ISBLANK(G14),"",SUMIF('Journal de bord'!N:N,G14,'Journal de bord'!K:K)) | J14: =IF(ISBLANK(I14),"",SUMIF('Journal de bord'!N:N,I14,'Journal de bord'!K:K)) | L14: =IF(ISBLANK(K14),"",SUMIF('Journal de bord'!N:N,K14,'Journal de bord'!K:K)) | N14: =IF(ISBLANK(M14),"",SUMIF('Journal de bord'!N:N,M14,'Journal de bord'!K:K)) | P14: =IF(ISBLANK(O14),"",SUMIF('Journal de bord'!N:N,O14,'Journal de bord'!K:K)) | R14: =IF(ISBLANK(Q14),"",SUMIF('Journal de bord'!N:N,Q14,'Journal de bord'!K:K)) | T14: =IF(ISBLANK(S14),"",SUMIF('Journal de bord'!N:N,S14,'Journal de bord'!K:K))
B15: =IF(ISBLANK(A15),"",SUMIF('Journal de bord'!N:N,A15,'Journal de bord'!K:K)) | D15: =IF(ISBLANK(C15),"",SUMIF('Journal de bord'!N:N,C15,'Journal de bord'!K:K)) | E15: Photos du matériel + optimisation UI | F15: =IF(ISBLANK(E15),"",SUMIF('Journal de bord'!N:N,E15,'Journal de bord'!K:K)) -> 0 | H15: =IF(ISBLANK(G15),"",SUMIF('Journal de bord'!N:N,G15,'Journal de bord'!K:K)) | J15: =IF(ISBLANK(I15),"",SUMIF('Journal de bord'!N:N,I15,'Journal de bord'!K:K)) | L15: =IF(ISBLANK(K15),"",SUMIF('Journal de bord'!N:N,K15,'Journal de bord'!K:K)) | N15: =IF(ISBLANK(M15),"",SUMIF('Journal de bord'!N:N,M15,'Journal de bord'!K:K)) | P15: =IF(ISBLANK(O15),"",SUMIF('Journal de bord'!N:N,O15,'Journal de bord'!K:K)) | R15: =IF(ISBLANK(Q15),"",SUMIF('Journal de bord'!N:N,Q15,'Journal de bord'!K:K)) | T15: =IF(ISBLANK(S15),"",SUMIF('Journal de bord'!N:N,S15,'Journal de bord'!K:K))
B16: =IF(ISBLANK(A16),"",SUMIF('Journal de bord'!N:N,A16,'Journal de bord'!K:K)) | D16: =IF(ISBLANK(C16),"",SUMIF('Journal de bord'!N:N,C16,'Journal de bord'!K:K)) | E16: Structure Html/CSS & logique JS | F16: =IF(ISBLANK(E16),"",SUMIF('Journal de bord'!N:N,E16,'Journal de bord'!K:K)) -> 0 | H16: =IF(ISBLANK(G16),"",SUMIF('Journal de bord'!N:N,G16,'Journal de bord'!K:K)) | J16: =IF(ISBLANK(I16),"",SUMIF('Journal de bord'!N:N,I16,'Journal de bord'!K:K)) | L16: =IF(ISBLANK(K16),"",SUMIF('Journal de bord'!N:N,K16,'Journal de bord'!K:K)) | N16: =IF(ISBLANK(M16),"",SUMIF('Journal de bord'!N:N,M16,'Journal de bord'!K:K)) | P16: =IF(ISBLANK(O16),"",SUMIF('Journal de bord'!N:N,O16,'Journal de bord'!K:K)) | R16: =IF(ISBLANK(Q16),"",SUMIF('Journal de bord'!N:N,Q16,'Journal de bord'!K:K)) | T16: =IF(ISBLANK(S16),"",SUMIF('Journal de bord'!N:N,S16,'Journal de bord'!K:K))
B17: =IF(ISBLANK(A17),"",SUMIF('Journal de bord'!N:N,A17,'Journal de bord'!K:K)) | D17: =IF(ISBLANK(C17),"",SUMIF('Journal de bord'!N:N,C17,'Journal de bord'!K:K)) | E17: Affichage | F17: =IF(ISBLANK(E17),"",SUMIF('Journal de bord'!N:N,E17,'Journal de bord'!K:K)) -> 0.076388889 | H17: =IF(ISBLANK(G17),"",SUMIF('Journal de bord'!N:N,G17,'Journal de bord'!K:K)) | J17: =IF(ISBLANK(I17),"",SUMIF('Journal de bord'!N:N,I17,'Journal de bord'!K:K)) | L17: =IF(ISBLANK(K17),"",SUMIF('Journal de bord'!N:N,K17,'Journal de bord'!K:K)) | N17: =IF(ISBLANK(M17),"",SUMIF('Journal de bord'!N:N,M17,'Journal de bord'!K:K)) | P17: =IF(ISBLANK(O17),"",SUMIF('Journal de bord'!N:N,O17,'Journal de bord'!K:K)) | R17: =IF(ISBLANK(Q17),"",SUMIF('Journal de bord'!N:N,Q17,'Journal de bord'!K:K)) | T17: =IF(ISBLANK(S17),"",SUMIF('Journal de bord'!N:N,S17,'Journal de bord'!K:K))
B18: =IF(ISBLANK(A18),"",SUMIF('Journal de bord'!N:N,A18,'Journal de bord'!K:K)) | D18: =IF(ISBLANK(C18),"",SUMIF('Journal de bord'!N:N,C18,'Journal de bord'!K:K)) | F18: =IF(ISBLANK(E18),"",SUMIF('Journal de bord'!N:N,E18,'Journal de bord'!K:K)) | H18: =IF(ISBLANK(G18),"",SUMIF('Journal de bord'!N:N,G18,'Journal de bord'!K:K)) | J18: =IF(ISBLANK(I18),"",SUMIF('Journal de bord'!N:N,I18,'Journal de bord'!K:K)) | L18: =IF(ISBLANK(K18),"",SUMIF('Journal de bord'!N:N,K18,'Journal de bord'!K:K)) | N18: =IF(ISBLANK(M18),"",SUMIF('Journal de bord'!N:N,M18,'Journal de bord'!K:K)) | P18: =IF(ISBLANK(O18),"",SUMIF('Journal de bord'!N:N,O18,'Journal de bord'!K:K)) | R18: =IF(ISBLANK(Q18),"",SUMIF('Journal de bord'!N:N,Q18,'Journal de bord'!K:K)) | T18: =IF(ISBLANK(S18),"",SUMIF('Journal de bord'!N:N,S18,'Journal de bord'!K:K))
B19: =IF(ISBLANK(A19),"",SUMIF('Journal de bord'!N:N,A19,'Journal de bord'!K:K)) | D19: =IF(ISBLANK(C19),"",SUMIF('Journal de bord'!N:N,C19,'Journal de bord'!K:K)) | F19: =IF(ISBLANK(E19),"",SUMIF('Journal de bord'!N:N,E19,'Journal de bord'!K:K)) | H19: =IF(ISBLANK(G19),"",SUMIF('Journal de bord'!N:N,G19,'Journal de bord'!K:K)) | J19: =IF(ISBLANK(I19),"",SUMIF('Journal de bord'!N:N,I19,'Journal de bord'!K:K)) | L19: =IF(ISBLANK(K19),"",SUMIF('Journal de bord'!N:N,K19,'Journal de bord'!K:K)) | N19: =IF(ISBLANK(M19),"",SUMIF('Journal de bord'!N:N,M19,'Journal de bord'!K:K)) | P19: =IF(ISBLANK(O19),"",SUMIF('Journal de bord'!N:N,O19,'Journal de bord'!K:K)) | R19: =IF(ISBLANK(Q19),"",SUMIF('Journal de bord'!N:N,Q19,'Journal de bord'!K:K)) | T19: =IF(ISBLANK(S19),"",SUMIF('Journal de bord'!N:N,S19,'Journal de bord'!K:K))
B20: =IF(ISBLANK(A20),"",SUMIF('Journal de bord'!N:N,A20,'Journal de bord'!K:K)) | D20: =IF(ISBLANK(C20),"",SUMIF('Journal de bord'!N:N,C20,'Journal de bord'!K:K)) | F20: =IF(ISBLANK(E20),"",SUMIF('Journal de bord'!N:N,E20,'Journal de bord'!K:K)) | H20: =IF(ISBLANK(G20),"",SUMIF('Journal de bord'!N:N,G20,'Journal de bord'!K:K)) | J20: =IF(ISBLANK(I20),"",SUMIF('Journal de bord'!N:N,I20,'Journal de bord'!K:K)) | L20: =IF(ISBLANK(K20),"",SUMIF('Journal de bord'!N:N,K20,'Journal de bord'!K:K)) | N20: =IF(ISBLANK(M20),"",SUMIF('Journal de bord'!N:N,M20,'Journal de bord'!K:K)) | P20: =IF(ISBLANK(O20),"",SUMIF('Journal de bord'!N:N,O20,'Journal de bord'!K:K)) | R20: =IF(ISBLANK(Q20),"",SUMIF('Journal de bord'!N:N,Q20,'Journal de bord'!K:K)) | T20: =IF(ISBLANK(S20),"",SUMIF('Journal de bord'!N:N,S20,'Journal de bord'!K:K))
B21: =IF(ISBLANK(A21),"",SUMIF('Journal de bord'!N:N,A21,'Journal de bord'!K:K)) | D21: =IF(ISBLANK(C21),"",SUMIF('Journal de bord'!N:N,C21,'Journal de bord'!K:K)) | F21: =IF(ISBLANK(E21),"",SUMIF('Journal de bord'!N:N,E21,'Journal de bord'!K:K)) | H21: =IF(ISBLANK(G21),"",SUMIF('Journal de bord'!N:N,G21,'Journal de bord'!K:K)) | J21: =IF(ISBLANK(I21),"",SUMIF('Journal de bord'!N:N,I21,'Journal de bord'!K:K)) | L21: =IF(ISBLANK(K21),"",SUMIF('Journal de bord'!N:N,K21,'Journal de bord'!K:K)) | N21: =IF(ISBLANK(M21),"",SUMIF('Journal de bord'!N:N,M21,'Journal de bord'!K:K)) | P21: =IF(ISBLANK(O21),"",SUMIF('Journal de bord'!N:N,O21,'Journal de bord'!K:K)) | R21: =IF(ISBLANK(Q21),"",SUMIF('Journal de bord'!N:N,Q21,'Journal de bord'!K:K)) | T21: =IF(ISBLANK(S21),"",SUMIF('Journal de bord'!N:N,S21,'Journal de bord'!K:K)) | U21: Total
A22: Total | B22: =SUM(B8:B21) -> 0.42708333 | C22: Total | D22: =SUM(D8:D21) -> 0 | E22: Total | F22: =SUM(F8:F21) -> 0.076388889 | G22: Total | H22: =SUM(H8:H21) -> 0 | I22: Total | J22: =SUM(J8:J21) -> 0 | K22: Total | L22: =SUM(L8:L21) -> 0 | M22: Total | N22: =SUM(N8:N21) -> 0 | O22: Total | P22: =SUM(P8:P21) -> 0 | Q22: Total | R22: =SUM(R8:R21) -> 0 | S22: Total | T22: =SUM(T8:T21) -> 0 | U22: =SUM(B22:T22) -> 0.50347222 | V22: h réelle
A23: =IF(ISBLANK(A5),"",A5) -> Administration | B23: =IF(B22=0,"",B22/$I4) -> 0.84827586 | C23: =IF(ISBLANK(C5),"",C5) -> Design /Preview | D23: =IF(D22=0,"",D22/$I4) | E23: =IF(ISBLANK(E5),"",E5) -> Code | F23: =IF(F22=0,"",F22/$I4) -> 0.15172414 | G23: =IF(ISBLANK(G5),"",G5) -> Base de données | H23: =IF(H22=0,"",H22/$I4) | I23: =IF(ISBLANK(I5),"",I5) -> Rendu au client | J23: =IF(J22=0,"",J22/$I4) | K23: =IF(ISBLANK(K5),"",K5) -> Achevement | L23: =IF(L22=0,"",L22/$I4) | M23: =IF(ISBLANK(M5),"",M5) | N23: =IF(N22=0,"",N22/$I4) | O23: =IF(ISBLANK(O5),"",O5) | P23: =IF(P22=0,"",P22/$I4) | Q23: =IF(ISBLANK(Q5),"",Q5) | R23: =IF(R22=0,"",R22/$I4) | S23: =IF(ISBLANK(S5),"",S5) | T23: =IF(T22=0,"",T22/$I4)
A24: Heures planifiées | U24: =SUM(B24:T24) -> 0 | V24: h planifiée
A25: Différences :
A26: h réelle > h planif | B26: =IF(B22>B24,B22-B24,"") -> 0.42708333 | D26: =IF(D22>D24,D22-D24,"") | F26: =IF(F22>F24,F22-F24,"") -> 0.076388889 | H26: =IF(H22>H24,H22-H24,"") | J26: =IF(J22>J24,J22-J24,"") | L26: =IF(L22>L24,L22-L24,"") | N26: =IF(N22>N24,N22-N24,"") | P26: =IF(P22>P24,P22-P24,"") | R26: =IF(R22>R24,R22-R24,"") | T26: =IF(T22>T24,T22-T24,"") | U26: =SUM(B26:T26) -> 0.50347222
A27: h réelle < h planif | B27: =IF(AND(B22=0,B24=0),"",IF(B22<B24,B24-B22,"")) | D27: =IF(AND(D22=0,D24=0),"",IF(D22<D24,D24-D22,"")) | F27: =IF(AND(F22=0,F24=0),"",IF(F22<F24,F24-F22,"")) | H27: =IF(AND(H22=0,H24=0),"",IF(H22<H24,H24-H22,"")) | J27: =IF(AND(J22=0,J24=0),"",IF(J22<J24,J24-J22,"")) | L27: =IF(AND(L22=0,L24=0),"",IF(L22<L24,L24-L22,"")) | N27: =IF(AND(N22=0,N24=0),"",IF(N22<N24,N24-N22,"")) | P27: =IF(AND(P22=0,P24=0),"",IF(P22<P24,P24-P22,"")) | R27: =IF(AND(R22=0,R24=0),"",IF(R22<R24,R24-R22,"")) | T27: =IF(AND(T22=0,T24=0),"",IF(T22<T24,T24-T22,"")) | U27: =SUM(B27:T27) -> 0
A29: Différence totale | C29: h réelle > h planif | D29: =IF(U22>U24,U22-U24,"") -> 0.50347222 | E29: h réelle < h planif | F29: =IF(U22<U24,U24-U22,"")
A32: =A23 -> Administration | B32: =B23 -> 0.84827586
A33: =C23 -> Design /Preview | B33: =D23
A34: =E23 -> Code | B34: =F23 -> 0.15172414
A35: =G23 -> Base de données | B35: =H23
A36: =I23 -> Rendu au client | B36: =J23
A37: =K23 -> Achevement | B37: =L23
A38: =M23 | B38: =N23
A39: =O23 | B39: =P23
A40: =Q23 | B40: =R23
A41: =S23 | B41: =T23

Sheet Aide-astuces Excel
A1: Aide et atuces Excel
A2: Liste déroulante
A3: Créer une liste déroulante de choix | B3: Données/Validation de données
A4: Créer une liste déroulante de choix en cascade | B4: idem + =indirect(cellule choix1)
A5: Définir un nom de plages de cellules | B5: Formules/Définir un nom/
A6: Gérer les noms des plages de cellules | B6: Formules/Gestionnaire de noms
A8: Organigramme
A9: Pour récupérer le texte de l'organigramme en une fois il faut copier/coller sur PowerPoint puis conception de SmartArt/convertir
A10: Attention de ne pas déplacer manuellement les zones de texte !
A12: Heures
A13: Astuce 1: si des #### apparaissent, il faut agrandir la largeur de la colonne
A14: Astuce 2 : pour des totaux de plus de 24h, format de cellule : [h]:mm;@
A15: Pour insérer le jour courant : Ctrl+Maj+;
A16: Pour insérer l'heure courante : Ctrl+Maj+:
A18: Verrouillage cellule/feuille
A19: Pour verrouiller/dévérouiller une cellule (seulement actif si la feuille est vérouillée) : clique droit/format de cellule/Protection
A20: Pour verrouiller/dévérouiller une feuille : menu Révision/Protégerla feuille-ôter la protection
A21: Mot de passe pour dévérouiller les feuilles si présent : vivelamedia /pas obligatoire de mettre un mot de passe
... A32: Menu Affichage, Figer les volets (soit par ligne, colonne ou les 2 => figer les volets en sélectionnant la première cellule qui va dérouler verticalement ou horizontalement)

Sheet Attention
D3: Attention
